Workbook
Name AcidityWaterSediment: #REF!
Name AcidityWaterSediment_range: #REF!
Name Biological_Treatment_Technology: #REF!
Name BiologicalTreatmentTechnology: #REF!
Name BiomassWaterSediment: #REF!
Name ColumnHeight: #REF!
Name Dissolvedoxygenconcentration: #REF!
Name InitialMassSediment: #REF!
Name Lifestage: '[1]Pick Lists'!#REF!
Name Method: '[1]Pick Lists'!#REF!
Name NitrogenContent: #REF!
Name OxygenDemand: #REF!
Name OxygenDemand_BOD5: #REF!
Name OxygenDemand_COD: #REF!
Name Oxygenuptakerate_OUR: #REF!
Name Parameter_definedtext: #REF!
Name Parameter_definedtext_Sludge: #REF!
Name Parameter_definedtext_Soil: #REF!
Name Parameter_definedtext_WS: #REF!
Name Parameter_freetext: #REF!
Name Parameter_freetext_Sludge: #REF!
Name Parameter_freetext_Soil: #REF!
Name Parameter_freetext_WS: #REF!
Name Parameter_numerical: #REF!
Name Parameter_numerical_Sludge: #REF!
Name Parameter_numerical_Soil: #REF!
Name Parameter_numerical_WS: #REF!
Name Parameter_numtype: #REF!
Name Parameter_numtype_Sludge: #REF!
Name Parameter_numtype_Soil: #REF!
Name Parameter_numtype_WS: #REF!
Name ParametersMeasured: #REF!
Name pH: #REF!
Name pH_range: #REF!
Name PhosphorusContent: #REF!
Name PurposeofWWTP: #REF!
Name Redoxcondition: #REF!
Name RedoxPotential: #REF!
Name Reliability: '[1]Pick Lists'!$D$1:$D$6
Name Route: '[1]Pick Lists'!#REF!
Name SamplingDepth: #REF!
Name Sludgeretentiontime: #REF!
Name SoilClassificationSystem: #REF!
Name SoilTexture1: #REF!
Name SoilTexture2: #REF!
Name Solventforcompoundaddition: #REF!
Name Species: '[1]Pick Lists'!#REF!
Name Species: '[1]Pick Lists'!#REF!
Name Temp: '[1]Pick Lists'!#REF!
Name Temp: '[1]Pick Lists'!#REF!
Name Type: #REF!
Name Typeofaeration: #REF!
Name Typeofcompoundaddition: #REF!

Sheet Description
A1: Information | B1: Entry
A2: Paper Title
A3: Description (will be uploaded)
A4: DOI
A5: Key | B5: e.g. Geng & Helbling, 2026
A6: Scenario Environment | B6: General
A7: Your Name | B7: Petra Muster
A8: Email Address | B8: p.muster@eawag.ch
A9: University/Company | B9: your institution

Sheet Compounds
A1: Type | B1: Name | C1: SMILES | D1: Alternative structure 1 | E1: Alternative structure 2 | F1: Alternative structure 3 | G1: Comment (not uploaded)
A2: Parent
A3: TP
A4: TP
A5: TP
A6: TP
A7: TP
A8: TP
A9: TP
A10: TP
A11: TP
A12: TP
A13: TP
... A50: TP

Sheet Connectivity
A1: Reactant | B1: Reactant_SMILES | C1: Product 1 | D1: Product_1_SMILES | E1: Product 2 | F1: Product_2_SMILES | G1: Multistep | H1: Transformation_Description | I1: Comment
B2: =_xlfn.XLOOKUP(A2,Compounds!$B$2:$B$50,Compounds!$C$2:$C$50) -> 0 | D2: =_xlfn.XLOOKUP(C2,Compounds!$B$2:$B$50,Compounds!$C$2:$C$50) -> 0 | F2: =_xlfn.XLOOKUP(E2,Compounds!$B$2:$B$50,Compounds!$C$2:$C$50) -> 0
B3: =_xlfn.XLOOKUP(A3,Compounds!$B$2:$B$50,Compounds!$C$2:$C$50) -> 0 | D3: =_xlfn.XLOOKUP(C3,Compounds!$B$2:$B$50,Compounds!$C$2:$C$50) -> 0 | F3: =_xlfn.XLOOKUP(E3,Compounds!$B$2:$B$50,Compounds!$C$2:$C$50) -> 0
B4: =_xlfn.XLOOKUP(A4,Compounds!$B$2:$B$50,Compounds!$C$2:$C$50) -> 0 | D4: =_xlfn.XLOOKUP(C4,Compounds!$B$2:$B$50,Compounds!$C$2:$C$50) -> 0 | F4: =_xlfn.XLOOKUP(E4,Compounds!$B$2:$B$50,Compounds!$C$2:$C$50) -> 0
B5: =_xlfn.XLOOKUP(A5,Compounds!$B$2:$B$50,Compounds!$C$2:$C$50) -> 0 | D5: =_xlfn.XLOOKUP(C5,Compounds!$B$2:$B$50,Compounds!$C$2:$C$50) -> 0 | F5: =_xlfn.XLOOKUP(E5,Compounds!$B$2:$B$50,Compounds!$C$2:$C$50) -> 0
B6: =_xlfn.XLOOKUP(A6,Compounds!$B$2:$B$50,Compounds!$C$2:$C$50) -> 0 | D6: =_xlfn.XLOOKUP(C6,Compounds!$B$2:$B$50,Compounds!$C$2:$C$50) -> 0 | F6: =_xlfn.XLOOKUP(E6,Compounds!$B$2:$B$50,Compounds!$C$2:$C$50) -> 0
B7: =_xlfn.XLOOKUP(A7,Compounds!$B$2:$B$50,Compounds!$C$2:$C$50) -> 0 | D7: =_xlfn.XLOOKUP(C7,Compounds!$B$2:$B$50,Compounds!$C$2:$C$50) -> 0 | F7: =_xlfn.XLOOKUP(E7,Compounds!$B$2:$B$50,Compounds!$C$2:$C$50) -> 0
B8: =_xlfn.XLOOKUP(A8,Compounds!$B$2:$B$50,Compounds!$C$2:$C$50) -> 0 | D8: =_xlfn.XLOOKUP(C8,Compounds!$B$2:$B$50,Compounds!$C$2:$C$50) -> 0 | F8: =_xlfn.XLOOKUP(E8,Compounds!$B$2:$B$50,Compounds!$C$2:$C$50) -> 0
B9: =_xlfn.XLOOKUP(A9,Compounds!$B$2:$B$50,Compounds!$C$2:$C$50) -> 0 | D9: =_xlfn.XLOOKUP(C9,Compounds!$B$2:$B$50,Compounds!$C$2:$C$50) -> 0 | F9: =_xlfn.XLOOKUP(E9,Compounds!$B$2:$B$50,Compounds!$C$2:$C$50) -> 0
B10: =_xlfn.XLOOKUP(A10,Compounds!$B$2:$B$50,Compounds!$C$2:$C$50) -> 0 | D10: =_xlfn.XLOOKUP(C10,Compounds!$B$2:$B$50,Compounds!$C$2:$C$50) -> 0 | F10: =_xlfn.XLOOKUP(E10,Compounds!$B$2:$B$50,Compounds!$C$2:$C$50) -> 0
B11: =_xlfn.XLOOKUP(A11,Compounds!$B$2:$B$50,Compounds!$C$2:$C$50) -> 0 | D11: =_xlfn.XLOOKUP(C11,Compounds!$B$2:$B$50,Compounds!$C$2:$C$50) -> 0 | F11: =_xlfn.XLOOKUP(E11,Compounds!$B$2:$B$50,Compounds!$C$2:$C$50) -> 0
B12: =_xlfn.XLOOKUP(A12,Compounds!$B$2:$B$50,Compounds!$C$2:$C$50) -> 0 | D12: =_xlfn.XLOOKUP(C12,Compounds!$B$2:$B$50,Compounds!$C$2:$C$50) -> 0 | F12: =_xlfn.XLOOKUP(E12,Compounds!$B$2:$B$50,Compounds!$C$2:$C$50) -> 0
B13: =_xlfn.XLOOKUP(A13,Compounds!$B$2:$B$50,Compounds!$C$2:$C$50) -> 0 | D13: =_xlfn.XLOOKUP(C13,Compounds!$B$2:$B$50,Compounds!$C$2:$C$50) -> 0 | F13: =_xlfn.XLOOKUP(E13,Compounds!$B$2:$B$50,Compounds!$C$2:$C$50) -> 0
... B50: =_xlfn.XLOOKUP(A50,Compounds!$B$2:$B$50,Compounds!$C$2:$C$50) -> 0 | D50: =_xlfn.XLOOKUP(C50,Compounds!$B$2:$B$50,Compounds!$C$2:$C$50) -> 0 | F50: =_xlfn.XLOOKUP(E50,Compounds!$B$2:$B$50,Compounds!$C$2:$C$50) -> 0

Sheet Scenario_Sludge
A1: Scenario Information | B1: Entry | C1: Scenario for Sludge Experiments | D1: Parameter | E1: Type | F1: Value | G1: Unit | H1: Range Type | I1: Comment
A2: Name | B2: =Description!B5 -> e.g. Geng & Helbling, 2026 | C2: Sludge Source | D2: Location
A3: Description | B3: =Description!B3 -> 0 | D3: Purpose of WWTP
D4: Biological treatment technology
D5: Inoculum Source
D6: Sludge retention time | G6: d
C7: Experimental Conditions | D7: Bioreactor | G7: mL
D8: Initial amount of sludge in bioreactor | G8: mL
D9: Addition of nutrients
D10: Organic content
D11: Organic content | E11: Organic Matter (OM) | G11: % | H11: low
D12: Organic content | E12: Organic Matter (OM) | G12: % | H12: high
D13: Organic content | E13: Organic Carbon (OC) | G13: % | H13: low
D14: Organic content | E14: Organic Carbon (OC) | G14: % | H14: high
D15: Cation exchange capacity, CEC | G15: mEq/100g
D16: Total suspended solids concentration (TSS) | G16: g/L | H16: Start
D17: Total suspended solids concentration (TSS) | G17: g/L | H17: End
D18: Volatile suspended solids concentration (VSS) | G18: g/L | H18: Start
D19: Volatile suspended solids concentration (VSS) | G19: g/L | H19: End
D20: Redox condition
D21: Type of Aeration
D22: Temperature | G22: °C | H22: min
D23: Temperature | G23: °C | H23: max
D24: pH | G24: NA | H24: low
D25: pH | G25: NA | H25: high
D26: Oxygen Demand | G26: mg/L | H26: Influent
D27: Oxygen Demand | G27: mg/L | H27: Effluent
D28: Nitrogen Content | G28: mg/L | H28: Influent
D29: Nitrogen Content | G29: mg/L | H29: Effluent
D30: Phosphorous Content | G30: mg/L | H30: Influent
D31: Phosphorous Content | G31: mg/L | H31: Effluent
D32: Source of liquid matrix
D33: Total organic carbon (TOC) | G33: mg C/L | H33: Start
D34: Total organic carbon (TOC) | G34: mg C/L | H34: End
D35: Dissolved organic carbon (DOC) | G35: mg C/L | H35: Start
D36: Dissolved organic carbon (DOC) | G36: mg C/L | H36: End
D37: Dissolved oxygen concentration | G37: mg/L | H37: low
D38: Dissolved oxygen concentration | G38: mg/L | H38: high
D39: Additional Parameters Measured
C40: Compound Addition | D40: Final compound concentration | G40: µg/L
...

Sheet Scenario_Soil
A1: Scenario Information | B1: Entry | C1: Scenario for Soil Experiments | D1: Parameter | E1: Type | F1: Value | G1: Unit | H1: Range Type | I1: Comment
A2: Name | B2: =Description!B5 -> e.g. Geng & Helbling, 2026 | C2: Soil source and properties | D2: Soil origin
A3: Description | B3: =Description!B3 -> 0 | D3: Soil texture
D4: Soil texture (%) | E4: sand | G4: %
D5: Soil texture (%) | E5: silt | G5: %
D6: Soil texture (%) | E6: clay | G6: %
D7: Soil texture classification system
C8: Experimental conditions | D8: Redox condition
D9: pH | G9: NA | H9: low
D10: pH | G10: NA | H10: high
D11: Temperature | G11: °C | H11: min
D12: Temperature | G12: °C | H12: max
D13: Experimental humidity | G13: %
D14: Experimental humidity | E14: Conditions
D15: Water storage capacity | G15: g water/100g dry soil
D16: Water storage capacity | G16: g water/100g dry soil
D17: Organic content
D18: Organic content | E18: Organic Matter (OM) | G18: % | H18: low
D19: Organic content | E19: Organic Matter (OM) | G19: % | H19: high
D20: Organic content | E20: Organic Carbon (OC) | G20: % | H20: low
D21: Organic content | E21: Organic Carbon (OC) | G21: % | H21: high
D22: Cation exchange capacity, CEC | G22: mEq/100g
D23: Bulk density | G23: g/cm3
D24: Microbial biomass | G24: µg C/g soil | H24: Start
D25: Microbial biomass | G25: µg C/g soil | H25: End
C26: Spike compound | D26: Spike compound structure | E26: SMILES
D27: Spike concentration
C28: Miscellaneous | D28: Study reliability
D29: Enzyme | E29: EC Number
D30: Reference
D31: Initiating organism
D32: Oxygen uptake rate (OUR) | G32: mg/L-h | H32: Start
D33: Oxygen uptake rate (OUR) | G33: mg/L-h | H33: End
D34: Ammonia uptake rate (AUR) | G34: mg/L-h | H34: Start
D35: Ammonia uptake rate (AUR) | G35: mg/L-h | H35: End
D36: Environment | F36: Soil

Sheet Scenario_Water-Sediment
A1: Scenario Information | B1: Entry | C1: Scenario for Water-Sediment Systems | D1: Parameter | E1: Type | F1: Value | G1: Unit | H1: Range Type | I1: Comment
A2: Name | B2: =Description!B5 -> e.g. Geng & Helbling, 2026 | C2: Sediment/water source and properties | D2: Sample location
A3: Description | B3: =Description!B3 -> 0 | D3: Sampling depth | G3: cm | H3: min
D4: Sampling depth | G4: cm | H4: max
D5: Soil origin
D6: Soil texture
D7: Soil texture (%) | E7: sand | G7: %
D8: Soil texture (%) | E8: silt | G8: %
D9: Soil texture (%) | E9: clay | G9: %
D10: Soil texture classification system
D11: Sediment porosity
C12: Experimental conditions | D12: Column height | E12: sediment | G12: cm
D13: Column height | E13: water | G13: cm
D14: Oxygen content | E14: water | G14: mg/L | H14: low
D15: Oxygen content | E15: water | G15: mg/L | H15: high
D16: Oxygen content | E16: sediment | G16: mg/L | H16: low
D17: Oxygen content | E17: sediment | G17: mg/L | H17: high
D18: Redox potential | E18: water | G18: mV | H18: low
D19: Redox potential | E19: water | G19: mV | H19: high
D20: Redox potential | E20: sediment | G20: mV | H20: low
D21: Redox potential | E21: sediment | G21: mV | H21: high
D22: pH in sediment | G22: NA | H22: low
D23: pH in sediment | G23: NA | H23: high
D24: pH in water | G24: NA | H24: low
D25: pH in water | G25: NA | H25: high
D26: Temperature | G26: °C | H26: min
D27: Temperature | G27: °C | H27: max
D28: Cation exchange capacity, CEC | G28: mEq/100g
D29: Organic content
D30: Organic content | E30: Organic Matter (OM) | G30: % | H30: low
D31: Organic content | E31: Organic Matter (OM) | G31: % | H31: high
D32: Organic content | E32: Organic Carbon (OC) | G32: % | H32: low
D33: Organic content | E33: Organic Carbon (OC) | G33: % | H33: high
D34: Microbial biomass in water | G34: cells/mL | H34: Start
D35: Microbial biomass in water | G35: cells/mL | H35: End
D36: Microbial biomass in sediment | G36: cells/g sediment | H36: Start
D37: Microbial biomass in sediment | G37: cells/g sediment | H37: End
D38: Microbial biomass in sediment | G38: mg C/g sediment | H38: Start
D39: Microbial biomass in sediment | G39: mg C/g sediment | H39: End
D40: Organic content in sediment | E40: Organic Matter (OM) | G40: % | H40: min
...

Sheet Scenario_General
A1: Scenario Information | B1: Entry | C1: Parameter | D1: Type | E1: Value | F1: Unit | G1: Range Type | H1: Comment
A2: Name | B2: =Description!B5 -> e.g. Geng & Helbling, 2026 | C2: Addition of nutrients
A3: Description | B3: =Description!B3 -> 0 | C3: Additional Parameters Measured
C4: Ammonia uptake rate (AUR) | F4: mg/L-h | G4: Start
C5: Ammonia uptake rate (AUR) | F5: mg/L-h | G5: End
C6: Biological treatment technology
C7: Bioreactor | F7: mL
C8: Bulk density | F8: g/cm3
C9: Cation exchange capacity, CEC | F9: mEq/100g
C10: Column height | D10: sediment | F10: cm
C11: Column height | D11: water | F11: cm
C12: Dissolved organic carbon (DOC) | F12: mg C/L | G12: Start
C13: Dissolved organic carbon (DOC) | F13: mg C/L | G13: End
C14: Dissolved oxygen concentration | F14: mg/L | G14: low
C15: Dissolved oxygen concentration | F15: mg/L | G15: high
C16: Enzyme | D16: Name
C17: Enzyme | D17: EC Number
C18: Experimental humidity | F18: %
C19: Experimental humidity | D19: Conditions
C20: Final compound concentration | F20: µg/L
C21: Initial amount of sludge in bioreactor | F21: mL
C22: Initial mass of sediment | D22: DRY | F22: g
C23: Initial mass of sediment | D23: WET | F23: g
C24: Initial volume of water | F24: mL
C25: Initiating organism
C26: Inoculum Source
C27: Location
C28: Microbial biomass | F28: µg C/g soil | G28: Start
C29: Microbial biomass | F29: µg C/g soil | G29: End
C30: Microbial biomass in sediment | F30: cells/g sediment | G30: Start
C31: Microbial biomass in sediment | F31: cells/g sediment | G31: End
C32: Microbial biomass in sediment | F32: mg C/g sediment | G32: Start
C33: Microbial biomass in sediment | F33: mg C/g sediment | G33: End
C34: Microbial biomass in water | F34: cells/mL | G34: Start
C35: Microbial biomass in water | F35: cells/mL | G35: End
C36: Nitrogen Content | F36: mg/L | G36: Influent
C37: Nitrogen Content | F37: mg/L | G37: Effluent
C38: Organic carbon in water layer | D38: Total Organic Carbon (TOC) | F38: mg/L | G38: low
C39: Organic carbon in water layer | D39: Total Organic Carbon (TOC) | F39: mg/L | G39: high
C40: Organic carbon in water layer | D40: Dissolved Organic Carbon (DOC) | F40: mg/L | G40: low
...

Sheet Kinetics_Confidence
A1: Scenario | B1: Compound | C1: SMILES | D1: Model | E1: Parameter | F1: Value | G1: Value Unit | H1: Corrected | I1: R2 | J1: Non-extractable (bound residues) at test end [%] | K1: Confidence Level_PFAS | L1: Confidence Level_Schy | M1: Major Product? | N1: Proposed Intermediate? | O1: Comment
A2: =Description!$B$5 -> e.g. Geng & Helbling, 2026 | C2: =_xlfn.XLOOKUP(B2,Compounds!$B$2:$B$50,Compounds!$C$2:$C$50) -> 0
A3: =Description!$B$5 -> e.g. Geng & Helbling, 2026 | C3: =_xlfn.XLOOKUP(B3,Compounds!$B$2:$B$50,Compounds!$C$2:$C$50) -> 0
A4: =Description!$B$5 -> e.g. Geng & Helbling, 2026 | C4: =_xlfn.XLOOKUP(B4,Compounds!$B$2:$B$50,Compounds!$C$2:$C$50) -> 0
A5: =Description!$B$5 -> e.g. Geng & Helbling, 2026 | C5: =_xlfn.XLOOKUP(B5,Compounds!$B$2:$B$50,Compounds!$C$2:$C$50) -> 0
A6: =Description!$B$5 -> e.g. Geng & Helbling, 2026 | C6: =_xlfn.XLOOKUP(B6,Compounds!$B$2:$B$50,Compounds!$C$2:$C$50) -> 0
A7: =Description!$B$5 -> e.g. Geng & Helbling, 2026 | C7: =_xlfn.XLOOKUP(B7,Compounds!$B$2:$B$50,Compounds!$C$2:$C$50) -> 0
A8: =Description!$B$5 -> e.g. Geng & Helbling, 2026 | C8: =_xlfn.XLOOKUP(B8,Compounds!$B$2:$B$50,Compounds!$C$2:$C$50) -> 0
A9: =Description!$B$5 -> e.g. Geng & Helbling, 2026 | C9: =_xlfn.XLOOKUP(B9,Compounds!$B$2:$B$50,Compounds!$C$2:$C$50) -> 0
A10: =Description!$B$5 -> e.g. Geng & Helbling, 2026 | C10: =_xlfn.XLOOKUP(B10,Compounds!$B$2:$B$50,Compounds!$C$2:$C$50) -> 0
A11: =Description!$B$5 -> e.g. Geng & Helbling, 2026 | C11: =_xlfn.XLOOKUP(B11,Compounds!$B$2:$B$50,Compounds!$C$2:$C$50) -> 0
A12: =Description!$B$5 -> e.g. Geng & Helbling, 2026 | C12: =_xlfn.XLOOKUP(B12,Compounds!$B$2:$B$50,Compounds!$C$2:$C$50) -> 0
A13: =Description!$B$5 -> e.g. Geng & Helbling, 2026 | C13: =_xlfn.XLOOKUP(B13,Compounds!$B$2:$B$50,Compounds!$C$2:$C$50) -> 0
... A50: =Description!$B$5 -> e.g. Geng & Helbling, 2026 | C50: =_xlfn.XLOOKUP(B50,Compounds!$B$2:$B$50,Compounds!$C$2:$C$50) -> 0
